<?xml version="1.0" ?>
<sdf version="1.10">
  <world name="simple_room_with_robot">
    <physics name="default_physics" type="dart">
      <max_step_size>0.001</max_step_size>
      <real_time_factor>1.0</real_time_factor>
    </physics>

    <plugin filename="libgz-sim-physics-system.so" name="gz::sim::systems::Physics"/>
    <plugin filename="libgz-sim-user-commands-system.so" name="gz::sim::systems::UserCommands"/>
    <plugin filename="libgz-sim-scene-broadcaster-system.so" name="gz::sim::systems::SceneBroadcaster"/>

    <light name="sun" type="directional">
      <cast_shadows>true</cast_shadows>
      <pose>0 0 10 0 0 0</pose>
      <diffuse>0.8 0.8 0.8 1</diffuse>
      <specular>0.2 0.2 0.2 1</specular>
      <attenuation>
        <range>1000</range>
        <constant>0.9</constant>
        <linear>0.01</linear>
        <quadratic>0.001</quadratic>
      </attenuation>
      <direction>-0.5 0.1 -1</direction>
    </light>

    <model name="ground_plane">
      <static>true</static>
      <link name="link">
        <collision name="collision">
          <geometry>
            <plane>
              <normal>0 0 1</normal>
              <size>50 50</size>
            </plane>
          </geometry>
        </collision>
        <visual name="visual">
          <geometry>
            <plane>
              <normal>0 0 1</normal>
              <size>50 50</size>
            </plane>
          </geometry>
          <material>
            <ambient>0.7 0.7 0.7 1</ambient>
            <diffuse>0.7 0.7 0.7 1</diffuse>
          </material>
        </visual>
      </link>
    </model>

    <model name="room_walls">
      <static>true</static>

      <link name="north_wall">
        <pose>0 3.05 1.25 0 0 0</pose>
        <collision name="collision">
          <geometry>
            <box>
              <size>6.10 0.10 2.50</size>
            </box>
          </geometry>
        </collision>
        <visual name="visual">
          <geometry>
            <box>
              <size>6.10 0.10 2.50</size>
            </box>
          </geometry>
          <material>
            <ambient>0.85 0.85 0.85 1</ambient>
            <diffuse>0.85 0.85 0.85 1</diffuse>
          </material>
        </visual>
      </link>

      <link name="east_wall">
        <pose>3.05 0 1.25 0 0 0</pose>
        <collision name="collision">
          <geometry>
            <box>
              <size>0.10 6.10 2.50</size>
            </box>
          </geometry>
        </collision>
        <visual name="visual">
          <geometry>
            <box>
              <size>0.10 6.10 2.50</size>
            </box>
          </geometry>
          <material>
            <ambient>0.85 0.85 0.85 1</ambient>
            <diffuse>0.85 0.85 0.85 1</diffuse>
          </material>
        </visual>
      </link>

      <link name="west_wall">
        <pose>-3.05 0 1.25 0 0 0</pose>
        <collision name="collision">
          <geometry>
            <box>
              <size>0.10 6.10 2.50</size>
            </box>
          </geometry>
        </collision>
        <visual name="visual">
          <geometry>
            <box>
              <size>0.10 6.10 2.50</size>
            </box>
          </geometry>
          <material>
            <ambient>0.85 0.85 0.85 1</ambient>
            <diffuse>0.85 0.85 0.85 1</diffuse>
          </material>
        </visual>
      </link>

      <link name="south_wall_left">
        <pose>-1.75 -3.05 1.25 0 0 0</pose>
        <collision name="collision">
          <geometry>
            <box>
              <size>2.50 0.10 2.50</size>
            </box>
          </geometry>
        </collision>
        <visual name="visual">
          <geometry>
            <box>
              <size>2.50 0.10 2.50</size>
            </box>
          </geometry>
          <material>
            <ambient>0.85 0.85 0.85 1</ambient>
            <diffuse>0.85 0.85 0.85 1</diffuse>
          </material>
        </visual>
      </link>

      <link name="south_wall_right">
        <pose>1.75 -3.05 1.25 0 0 0</pose>
        <collision name="collision">
          <geometry>
            <box>
              <size>2.50 0.10 2.50</size>
            </box>
          </geometry>
        </collision>
        <visual name="visual">
          <geometry>
            <box>
              <size>2.50 0.10 2.50</size>
            </box>
          </geometry>
          <material>
            <ambient>0.85 0.85 0.85 1</ambient>
            <diffuse>0.85 0.85 0.85 1</diffuse>
          </material>
        </visual>
      </link>

      <link name="south_wall_header">
        <pose>0 -3.05 2.30 0 0 0</pose>
        <collision name="collision">
          <geometry>
            <box>
              <size>1.10 0.10 0.40</size>
            </box>
          </geometry>
        </collision>
        <visual name="visual">
          <geometry>
            <box>
              <size>1.10 0.10 0.40</size>
            </box>
          </geometry>
          <material>
            <ambient>0.85 0.85 0.85 1</ambient>
            <diffuse>0.85 0.85 0.85 1</diffuse>
          </material>
        </visual>
      </link>
      
      <include>
        <name>Couch0</name>
        <pose>-0.8 1.3 0 0 0 0</pose>
        <uri>
          https://fuel.gazebosim.org/1.0/OpenRobotics/models/Sofa
        </uri>
      </include>

      <joint name="north_to_east" type="fixed">
        <parent>north_wall</parent>
        <child>east_wall</child>
      </joint>
      <joint name="north_to_west" type="fixed">
        <parent>north_wall</parent>
        <child>west_wall</child>
      </joint>
      <joint name="north_to_south_left" type="fixed">
        <parent>north_wall</parent>
        <child>south_wall_left</child>
      </joint>
      <joint name="north_to_south_right" type="fixed">
        <parent>north_wall</parent>
        <child>south_wall_right</child>
      </joint>
      <joint name="north_to_south_header" type="fixed">
        <parent>north_wall</parent>
        <child>south_wall_header</child>
      </joint>
    </model>

    <model name="vehicle_blue" canonical_link="chassis">
      <pose>0 0 0 0 0 0</pose>
      
      <frame name="lidar_frame" attached_to='chassis'>
        <pose>0.8 0 0.5 0 0 0</pose>
      </frame>
      
      <link name="chassis">
        <pose>0 0 0.18 0 0 0</pose>
        <inertial>
          <mass>5.0</mass>
          <inertia>
            <ixx>0.03</ixx>
            <ixy>0</ixy>
            <ixz>0</ixz>
            <iyy>0.03</iyy>
            <iyz>0</iyz>
            <izz>0.03</izz>
          </inertia>
        </inertial>
        <visual name="visual">
          <geometry>
            <box>
              <size>0.50 0.35 0.20</size>
            </box>
          </geometry>
          <material>
            <ambient>0.0 0.0 1.0 1</ambient>
            <diffuse>0.0 0.0 1.0 1</diffuse>
            <specular>0.0 0.0 1.0 1</specular>
          </material>
        </visual>
        <collision name="collision">
          <geometry>
            <box>
              <size>0.50 0.35 0.20</size>
            </box>
          </geometry>
        </collision>
        <sensor name='gpu_lidar' type='gpu_lidar'>
          <pose relative_to='lidar_frame'>0 0 0 0 0 0</pose>
          <topic>/lidar</topic>
          <update_rate>10</update_rate>
          <ray>
            <scan>
               <horizontal>
               <samples>640</samples>
               <resolution>1</resolution>
               <min_angle>-1.396263</min_angle>
               <max_angle>1.396263</max_angle>
               </horizontal>
               <vertical>
               <samples>1</samples>
               <resolution>0.01</resolution>
               <min_angle>0</min_angle>
               <max_angle>0</max_angle>
               </vertical>
               </scan>
         <range>
          <min>0.08</min>
          <max>10.0</max>
          <resolution>0.01</resolution>
        </range>
        </ray>
        <always_on>1</always_on>
        <visualize>true</visualize>
       </sensor>
      </link>

      <link name="left_wheel">
        <pose relative_to="chassis">-0.15 0.18 -0.10 -1.5707 0 0</pose>
        <inertial>
          <mass>0.5</mass>
          <inertia>
            <ixx>0.001</ixx>
            <ixy>0</ixy>
            <ixz>0</ixz>
            <iyy>0.001</iyy>
            <iyz>0</iyz>
            <izz>0.001</izz>
          </inertia>
        </inertial>
        <visual name="visual">
          <geometry>
            <cylinder>
              <radius>0.08</radius>
              <length>0.05</length>
            </cylinder>
          </geometry>
          <material>
            <ambient>1.0 0.0 0.0 1</ambient>
            <diffuse>1.0 0.0 0.0 1</diffuse>
            <specular>1.0 0.0 0.0 1</specular>
          </material>
        </visual>
        <collision name="collision">
          <geometry>
            <cylinder>
              <radius>0.08</radius>
              <length>0.05</length>
            </cylinder>
          </geometry>
        </collision>
      </link>

      <link name="right_wheel">
        <pose relative_to="chassis">-0.15 -0.18 -0.10 -1.5707 0 0</pose>
        <inertial>
          <mass>0.5</mass>
          <inertia>
            <ixx>0.001</ixx>
            <ixy>0</ixy>
            <ixz>0</ixz>
            <iyy>0.001</iyy>
            <iyz>0</iyz>
            <izz>0.001</izz>
          </inertia>
        </inertial>
        <visual name="visual">
          <geometry>
            <cylinder>
              <radius>0.08</radius>
              <length>0.05</length>
            </cylinder>
          </geometry>
          <material>
            <ambient>1.0 0.0 0.0 1</ambient>
            <diffuse>1.0 0.0 0.0 1</diffuse>
            <specular>1.0 0.0 0.0 1</specular>
          </material>
        </visual>
        <collision name="collision">
          <geometry>
            <cylinder>
              <radius>0.08</radius>
              <length>0.05</length>
            </cylinder>
          </geometry>
        </collision>
      </link>

      <frame name="caster_frame" attached_to="chassis">
        <pose>0.20 0 -0.14 0 0 0</pose>
      </frame>

      <link name="caster">
        <pose relative_to="caster_frame">0 0 0 0 0 0</pose>
        <inertial>
          <mass>0.2</mass>
          <inertia>
            <ixx>0.0002</ixx>
            <ixy>0</ixy>
            <ixz>0</ixz>
            <iyy>0.0002</iyy>
            <iyz>0</iyz>
            <izz>0.0002</izz>
          </inertia>
        </inertial>
        <visual name="visual">
          <geometry>
            <sphere>
              <radius>0.04</radius>
            </sphere>
          </geometry>
          <material>
            <ambient>0.0 1 0.0 1</ambient>
            <diffuse>0.0 1 0.0 1</diffuse>
            <specular>0.0 1 0.0 1</specular>
          </material>
        </visual>
        <collision name="collision">
          <geometry>
            <sphere>
              <radius>0.04</radius>
            </sphere>
          </geometry>
        </collision>
      </link>

      <joint name="left_wheel_joint" type="revolute">
        <pose relative_to="left_wheel">0 0 0 0 0 0</pose>
        <parent>chassis</parent>
        <child>left_wheel</child>
        <axis>
          <xyz expressed_in="__model__">0 1 0</xyz>
          <limit>
            <lower>-1.79769e+308</lower>
            <upper>1.79769e+308</upper>
          </limit>
        </axis>
      </joint>

      <joint name="right_wheel_joint" type="revolute">
        <pose relative_to="right_wheel">0 0 0 0 0 0</pose>
        <parent>chassis</parent>
        <child>right_wheel</child>
        <axis>
          <xyz expressed_in="__model__">0 1 0</xyz>
          <limit>
            <lower>-1.79769e+308</lower>
            <upper>1.79769e+308</upper>
          </limit>
        </axis>
      </joint>

      <joint name="caster_wheel" type="ball">
        <parent>chassis</parent>
        <child>caster</child>
      </joint>

      <plugin filename="libgz-sim-diff-drive-system.so" name="gz::sim::systems::DiffDrive">
        <left_joint>left_wheel_joint</left_joint>
        <right_joint>right_wheel_joint</right_joint>
        <wheel_separation>0.36</wheel_separation>
        <wheel_radius>0.08</wheel_radius>
        <odom_publish_frequency>1</odom_publish_frequency>
        <topic>/cmd_vel</topic>
      </plugin>
    </model>


    <plugin filename="libgz-sim-triggered-publisher-system.so" name="gz::sim::systems::TriggeredPublisher">
      <input type="gz.msgs.Int32" topic="/keyboard/keypress">
        <match field="data">16777234</match>
      </input>
      <output type="gz.msgs.Twist" topic="/cmd_vel">
        linear: {x: 0.0}, angular: {z: 0.5}
      </output>
    </plugin>

    <plugin filename="libgz-sim-triggered-publisher-system.so" name="gz::sim::systems::TriggeredPublisher">
      <input type="gz.msgs.Int32" topic="/keyboard/keypress">
        <match field="data">16777235</match>
      </input>
      <output type="gz.msgs.Twist" topic="/cmd_vel">
        linear: {x: 0.5}, angular: {z: 0.0}
      </output>
    </plugin>

    <plugin filename="libgz-sim-triggered-publisher-system.so" name="gz::sim::systems::TriggeredPublisher">
      <input type="gz.msgs.Int32" topic="/keyboard/keypress">
        <match field="data">16777236</match>
      </input>
      <output type="gz.msgs.Twist" topic="/cmd_vel">
        linear: {x: 0.0}, angular: {z: -0.5}
      </output>
    </plugin>

    <plugin filename="libgz-sim-triggered-publisher-system.so" name="gz::sim::systems::TriggeredPublisher">
      <input type="gz.msgs.Int32" topic="/keyboard/keypress">
        <match field="data">16777237</match>
      </input>
      <output type="gz.msgs.Twist" topic="/cmd_vel">
        linear: {x: -0.5}, angular: {z: 0.0}
      </output>
    </plugin>

    <plugin filename="libgz-sim-sensors-system.so" name="gz::sim::systems::Sensors"/>
    <plugin filename="libgz-sim-imu-system.so" name="gz::sim::systems::Imu"/>

  </world>
</sdf>
