<?xml version="1.0"?>
<robot name="vehicle">

  <!-- Base -->
  <link name="chassis"/>

  <!-- Torso -->
  <link name="torso"/>

  <!-- Torso -->
  <link name="head"/>

  <!-- Wheels -->
  <link name="left_front_wheel"/>
  <link name="right_front_wheel"/>
  <link name="left_back_wheel"/>
  <link name="right_back_wheel"/>

  <!-- Joints -->

  <joint name="left_front_wheel_joint" type="continuous">
    <parent link="chassis"/>
    <child link="left_front_wheel"/>
    <origin xyz="0.15 0.18 -0.10" rpy="-1.5707 0 0"/>
    <axis xyz="0 1 0"/>
  </joint>

  <joint name="right_front_wheel_joint" type="continuous">
    <parent link="chassis"/>
    <child link="right_front_wheel"/>
    <origin xyz="0.15 -0.18 -0.10" rpy="-1.5707 0 0"/>
    <axis xyz="0 1 0"/>
  </joint>

  <joint name="left_back_wheel_joint" type="continuous">
    <parent link="chassis"/>
    <child link="left_back_wheel"/>
    <origin xyz="-0.15 0.18 -0.10" rpy="-1.5707 0 0"/>
    <axis xyz="0 1 0"/>
  </joint>

  <joint name="right_back_wheel_joint" type="continuous">
    <parent link="chassis"/>
    <child link="right_back_wheel"/>
    <origin xyz="-0.15 -0.18 -0.10" rpy="-1.5707 0 0"/>
    <axis xyz="0 1 0"/>
  </joint>

  <joint name="torso_joint" type="fixed">
    <parent link="chassis"/>
    <child link="torso"/>
    <origin xyz="0 0 0.22" rpy="0 0 0"/>
  </joint>

  <joint name="head_joint" type="fixed">
    <parent link="torso"/>
    <child link="head"/>
    <origin xyz="0.02 0.08 0.05" rpy="0 0 0"/>
  </joint>

  <link name="camera_link"/>
  <joint name="camera_joint" type="fixed">
    <parent link="torso"/>
    <child link="camera_link"/>
    <origin xyz="0.08 0 0.08" rpy="0 0 0"/>
  </joint>

  <ros2_control name="GazeboSimSystem" type="system">
    <hardware>
      <plugin>gz_ros2_control/GazeboSimSystem</plugin>
    </hardware>

    <joint name="left_front_wheel_joint">
      <command_interface name="velocity"/>
      <state_interface name="position"/>
      <state_interface name="velocity"/>
    </joint>

    <joint name="right_front_wheel_joint">
      <command_interface name="velocity"/>
      <state_interface name="position"/>
      <state_interface name="velocity"/>
    </joint>

    <joint name="left_back_wheel_joint">
      <command_interface name="velocity"/>
      <state_interface name="position"/>
      <state_interface name="velocity"/>
    </joint>

    <joint name="right_back_wheel_joint">
      <command_interface name="velocity"/>
      <state_interface name="position"/>
      <state_interface name="velocity"/>
    </joint>
  </ros2_control>
  
</robot>